Workbook

Sheet 파괴조사 데이터
A1: 날짜 | B1: Treatment | C1: Repeat | D1: SPAD | E1: 엽장 | F1: 엽폭 | G1: 엽수 | H1: 엽면적 | I1: 지상부 생체중 | L1: 지상부 건조중 | O1: 지하부 건조중 (배지 포함) | P1: 지하부 건조중 | Q1: 포화중(TW) | R1: LSI (cm/cm) | S1: SLA (cm2/g) | T1: S/R ratio (g/g) | U1: RWC(%) | W1: 포화 시간에 따른 포화중(TW)
I2: TW측정용 | J2: 나머지 | K2: 전체 | L2: TW측정용 | M2: 나머지 | N2: 전체 | W2: 1h | X2: 2h | Y2: 22.5h | Z2: 25h
A3: 2026-10-07 | B3: CR | C3: 1 | D3: 38.5 | E3: 15.4 | F3: 7.8 | G3: 15 | H3: 340.15 | I3: 2.48 | J3: 10.28 | K3: =I3+J3 -> 12.76 | L3: 0.113 | M3: 0.515 | N3: =L3+M3 -> 0.628 | O3: 0.634 | P3: =O3-0.22 -> 0.414 | Q3: 2.6 | R3: =E3/F3 -> 1.974359 | S3: =H3/N3 -> 541.64013 | T3: =N3/P3 -> 1.5169082 | U3: =(I3-L3)/(Q3-L3)*100 -> 95.17491 | W3: 2.52 | X3: 2.49 | Y3: 2.6 | Z3: 2.59
A4: 2026-10-07 | B4: CR | C4: 2 | D4: 41.1 | E4: 16 | F4: 7.6 | G4: 15 | H4: 371.45 | I4: 2.92 | J4: 12.47 | K4: =I4+J4 -> 15.39 | L4: 0.125 | M4: 0.613 | N4: =L4+M4 -> 0.738 | O4: 1.187 | P4: =O4-0.22 -> 0.967 | Q4: 3.1 | R4: =E4/F4 -> 2.1052632 | S4: =H4/N4 -> 503.31978 | T4: =N4/P4 -> 0.76318511 | U4: =(I4-L4)/(Q4-L4)*100 -> 93.94958 | W4: 3.02 | X4: 2.96 | Y4: 3.1 | Z4: 3.1
A5: 2026-10-07 | B5: CR | C5: 3 | D5: 41.1 | E5: 15.2 | F5: 7.7 | G5: 14 | H5: 304.21 | I5: 3.13 | J5: 9.98 | K5: =I5+J5 -> 13.11 | L5: 0.137 | M5: 0.493 | N5: =L5+M5 -> 0.63 | O5: 0.908 | P5: =O5-0.22 -> 0.688 | Q5: 3.5 | R5: =E5/F5 -> 1.974026 | S5: =H5/N5 -> 482.87302 | T5: =N5/P5 -> 0.91569767 | U5: =(I5-L5)/(Q5-L5)*100 -> 88.997919 | W5: 3.27 | X5: 3.27 | Y5: 3.5 | Z5: 3.52
A6: 2026-10-07 | B6: CR | C6: 4 | D6: 40.3 | E6: 11.9 | F6: 6.8 | G6: 13 | H6: 227.88 | I6: 1.73 | J6: 6.7 | K6: =I6+J6 -> 8.43 | L6: 0.106 | M6: 0.465 | N6: =L6+M6 -> 0.571 | O6: 0.658 | P6: =O6-0.22 -> 0.438 | Q6: 1.96 | R6: =E6/F6 -> 1.75 | S6: =H6/N6 -> 399.08932 | T6: =N6/P6 -> 1.303653 | U6: =(I6-L6)/(Q6-L6)*100 -> 87.594391 | W6: 1.76 | X6: 1.78 | Y6: 1.96 | Z6: 1.98
A7: 2026-10-07 | B7: CR | C7: 5 | D7: 44.6 | E7: 11.4 | F7: 6.3 | G7: 12 | H7: 204.12 | I7: 1.74 | J7: 5.06 | K7: =I7+J7 -> 6.8 | L7: 0.104 | M7: 0.363 | N7: =L7+M7 -> 0.467 | O7: 0.869 | P7: =O7-0.22 -> 0.649 | Q7: 2.07 | R7: =E7/F7 -> 1.8095238 | S7: =H7/N7 -> 437.08779 | T7: =N7/P7 -> 0.71956857 | U7: =(I7-L7)/(Q7-L7)*100 -> 83.214649 | W7: 1.76 | X7: 1.78 | Y7: 2.07 | Z7: 2.1
A8: 2026-10-07 | B8: CR | C8: 6 | D8: 37.6 | E8: 9.9 | F8: 6.2 | G8: 10 | H8: 173.69 | I8: 1.23 | J8: 4.29 | K8: =I8+J8 -> 5.52 | L8: 0.064 | M8: 0.305 | N8: =L8+M8 -> 0.369 | O8: 0.967 | P8: =O8-0.22 -> 0.747 | Q8: 1.45 | R8: =E8/F8 -> 1.5967742 | S8: =H8/N8 -> 470.70461 | T8: =N8/P8 -> 0.4939759 | U8: =(I8-L8)/(Q8-L8)*100 -> 84.126984 | W8: 1.28 | X8: 1.26 | Y8: 1.45 | Z8: 1.46
A9: 2026-10-07 | B9: CR | C9: 7 | D9: 37.6 | E9: 11.9 | F9: 6.1 | G9: 14 | H9: 247.6 | I9: 1.82 | J9: 8.01 | K9: =I9+J9 -> 9.83 | L9: 0.112 | M9: 0.552 | N9: =L9+M9 -> 0.664 | O9: 1.418 | P9: =O9-0.22 -> 1.198 | Q9: 2.12 | R9: =E9/F9 -> 1.9508197 | S9: =H9/N9 -> 372.89157 | T9: =N9/P9 -> 0.5542571 | U9: =(I9-L9)/(Q9-L9)*100 -> 85.059761 | W9: 1.86 | X9: 1.89 | Y9: 2.12 | Z9: 2.13
A10: 2026-10-07 | B10: CR | C10: 8 | D10: 40.6 | E10: 13.3 | F10: 7.1 | G10: 14 | H10: 216.17 | I10: 2.26 | J10: 6.13 | K10: =I10+J10 -> 8.39 | L10: 0.117 | M10: 0.391 | N10: =L10+M10 -> 0.508 | O10: 0.673 | P10: =O10-0.22 -> 0.453 | Q10: 2.6 | R10: =E10/F10 -> 1.8732394 | S10: =H10/N10 -> 425.5315 | T10: =N10/P10 -> 1.1214128 | U10: =(I10-L10)/(Q10-L10)*100 -> 86.306887 | W10: 2.28 | X10: 2.29 | Y10: 2.6 | Z10: 2.6
A11: 2026-10-23 | B11: CR | C11: 1 | D11: 48.3 | E11: 17 | F11: 9 | G11: 37 | H11: 1518.74 | I11: 6.36 | J11: 74.54 | K11: =I11+J11 -> 80.9 | L11: 0.579 | M11: 6.94 | N11: =L11+M11 -> 7.519 | O11: 5.96 | P11: =O11-0.22 -> 5.74 | Q11: 7 | R11: =E11/F11 -> 1.8888889 | S11: =H11/N11 -> 201.98697 | T11: =N11/P11 -> 1.3099303 | U11: =(I11-L11)/(Q11-L11)*100 -> 90.032705
A12: 2026-10-23 | B12: CR | C12: 2 | D12: 42.8 | E12: 16.5 | F12: 10 | G12: 34 | H12: 1648.8 | I12: 8.02 | J12: 92.6 | K12: =I12+J12 -> 100.62 | L12: 0.454 | M12: 5.89 | N12: =L12+M12 -> 6.344 | O12: 4.51 | P12: =O12-0.22 -> 4.29 | Q12: 8.95 | R12: =E12/F12 -> 1.65 | S12: =H12/N12 -> 259.89912 | T12: =N12/P12 -> 1.4787879 | U12: =(I12-L12)/(Q12-L12)*100 -> 89.053672
A13: 2026-10-23 | B13: CR | C13: 3 | D13: 44.8 | E13: 13.5 | F13: 9 | G13: 39 | H13: 1667.14 | I13: 5.45 | J13: 89.3 | K13: =I13+J13 -> 94.75 | L13: 0.37 | M13: 5.95 | N13: =L13+M13 -> 6.32 | O13: 4.23 | P13: =O13-0.22 -> 4.01 | Q13: 5.59 | R13: =E13/F13 -> 1.5 | S13: =H13/N13 -> 263.78797 | T13: =N13/P13 -> 1.5760599 | U13: =(I13-L13)/(Q13-L13)*100 -> 97.318008
A14: 2026-10-23 | B14: CR | C14: 4 | D14: 45.6 | E14: 15.5 | F14: 9 | G14: 33 | H14: 1395.68 | J14: 89.64 | K14: =I14+J14 -> 89.64 | M14: 4.78 | N14: =L14+M14 -> 4.78 | O14: 6.18 | P14: =O14-0.22 -> 5.96 | R14: =E14/F14 -> 1.7222222 | S14: =H14/N14 -> 291.98326 | T14: =N14/P14 -> 0.80201342
A15: 2026-10-23 | B15: CR | C15: 5 | D15: 41.9 | E15: 15 | F15: 8 | G15: 33 | H15: 1399.98 | J15: 80.95 | K15: =I15+J15 -> 80.95 | M15: 4.71 | N15: =L15+M15 -> 4.71 | O15: 1.97 | P15: =O15-0.22 -> 1.75 | R15: =E15/F15 -> 1.875 | S15: =H15/N15 -> 297.23567 | T15: =N15/P15 -> 2.6914286
A16: 2026-10-23 | B16: CR | C16: 6 | D16: 36.3 | E16: 17 | F16: 8.5 | G16: 38 | H16: 1905.42 | J16: 103.78 | K16: =I16+J16 -> 103.78 | M16: 7.01 | N16: =L16+M16 -> 7.01 | O16: 3.38 | P16: =O16-0.22 -> 3.16 | R16: =E16/F16 -> 2 | S16: =H16/N16 -> 271.81455 | T16: =N16/P16 -> 2.2183544
A17: 2026-10-23 | B17: CR | C17: 7 | D17: 41 | E17: 18 | F17: 9.5 | G17: 36 | H17: 1861.64 | J17: 98.39 | K17: =I17+J17 -> 98.39 | M17: 7.41 | N17: =L17+M17 -> 7.41 | O17: 4.56 | P17: =O17-0.22 -> 4.34 | R17: =E17/F17 -> 1.8947368 | S17: =H17/N17 -> 251.23347 | T17: =N17/P17 -> 1.7073733
A18: 2026-10-23 | B18: CR | C18: 8 | D18: 44.8 | E18: 17.5 | F18: 9 | G18: 35 | H18: 1397.27 | J18: 70.05 | K18: =I18+J18 -> 70.05 | M18: 7.68 | N18: =L18+M18 -> 7.68 | O18: 6.64 | P18: =O18-0.22 -> 6.42 | R18: =E18/F18 -> 1.9444444 | S18: =H18/N18 -> 181.9362 | T18: =N18/P18 -> 1.1962617
A19: 2026-10-23 | B19: DR | C19: 1 | D19: 38.3 | E19: 17.5 | F19: 9 | G19: 31 | H19: 1209.94 | I19: 4.83 | J19: 51.41 | K19: =I19+J19 -> 56.24 | L19: 0.46 | M19: 5.35 | N19: =L19+M19 -> 5.81 | O19: 4.86 | P19: =O19-0.22 -> 4.64 | Q19: 5.34 | R19: =E19/F19 -> 1.9444444 | S19: =H19/N19 -> 208.25129 | T19: =N19/P19 -> 1.2521552 | U19: =(I19-L19)/(Q19-L19)*100 -> 89.54918
A20: 2026-10-23 | B20: DR | C20: 2 | D20: 46.1 | E20: 15 | F20: 9 | G20: 33 | H20: 1424.04 | I20: 5.04 | J20: 67.73 | K20: =I20+J20 -> 72.77 | L20: 0.347 | M20: 5.19 | N20: =L20+M20 -> 5.537 | O20: 2.36 | P20: =O20-0.22 -> 2.14 | Q20: 5.75 | R20: =E20/F20 -> 1.6666667 | S20: =H20/N20 -> 257.1862 | T20: =N20/P20 -> 2.5873832 | U20: =(I20-L20)/(Q20-L20)*100 -> 86.859152
A21: 2026-10-23 | B21: DR | C21: 3 | D21: 44.1 | E21: 15.5 | F21: 8.4 | G21: 30 | H21: 1117.81 | I21: 4.13 | J21: 52.58 | K21: =I21+J21 -> 56.71 | L21: 0.277 | M21: 4.15 | N21: =L21+M21 -> 4.427 | O21: 3.46 | P21: =O21-0.22 -> 3.24 | Q21: 4.39 | R21: =E21/F21 -> 1.8452381 | S21: =H21/N21 -> 252.49831 | T21: =N21/P21 -> 1.366358 | U21: =(I21-L21)/(Q21-L21)*100 -> 93.67858
A22: 2026-10-23 | B22: DR | C22: 4 | D22: 41.1 | E22: 17 | F22: 9.2 | G22: 31 | H22: 1288.94 | J22: 61.44 | K22: =I22+J22 -> 61.44 | M22: 5.78 | N22: =L22+M22 -> 5.78 | O22: 3.71 | P22: =O22-0.22 -> 3.49 | R22: =E22/F22 -> 1.8478261 | S22: =H22/N22 -> 223 | T22: =N22/P22 -> 1.6561605
A23: 2026-10-23 | B23: DR | C23: 5 | D23: 50.5 | E23: 15 | F23: 10 | G23: 31 | H23: 1311.35 | J23: 66.31 | K23: =I23+J23 -> 66.31 | M23: 5.15 | N23: =L23+M23 -> 5.15 | O23: 2.67 | P23: =O23-0.22 -> 2.45 | R23: =E23/F23 -> 1.5 | S23: =H23/N23 -> 254.63107 | T23: =N23/P23 -> 2.1020408
A24: 2026-10-23 | B24: DR | C24: 6 | D24: 42.8 | E24: 17 | F24: 9 | G24: 33 | H24: 1444.84 | J24: 67.29 | K24: =I24+J24 -> 67.29 | M24: 6.01 | N24: =L24+M24 -> 6.01 | O24: 2.75 | P24: =O24-0.22 -> 2.53 | R24: =E24/F24 -> 1.8888889 | S24: =H24/N24 -> 240.40599 | T24: =N24/P24 -> 2.3754941
A25: 2026-10-23 | B25: DR | C25: 7 | D25: 51.1 | E25: 16 | F25: 8.7 | G25: 31 | H25: 1226.55 | J25: 60.49 | K25: =I25+J25 -> 60.49 | M25: 4.76 | N25: =L25+M25 -> 4.76 | O25: 1.63 | P25: =O25-0.22 -> 1.41 | R25: =E25/F25 -> 1.8390805 | S25: =H25/N25 -> 257.67857 | T25: =N25/P25 -> 3.3758865
A26: 2026-10-23 | B26: DR | C26: 8 | D26: 41.9 | E26: 17.2 | F26: 8.5 | G26: 29 | H26: 1290.95 | J26: 66.52 | K26: =I26+J26 -> 66.52 | M26: 5.97 | N26: =L26+M26 -> 5.97 | O26: 1.96 | P26: =O26-0.22 -> 1.74 | R26: =E26/F26 -> 2.0235294 | S26: =H26/N26 -> 216.23953 | T26: =N26/P26 -> 3.4310345
A27: 2026-10-23 | B27: WR | C27: 1 | D27: 38.7 | E27: 15 | F27: 8 | G27: 31 | H27: 1367.97 | I27: 3.71 | J27: 60.19 | K27: =I27+J27 -> 63.9 | L27: 0.252 | M27: 3.99 | N27: =L27+M27 -> 4.242 | O27: 2.81 | P27: =O27-0.22 -> 2.59 | Q27: 4.06 | R27: =E27/F27 -> 1.875 | S27: =H27/N27 -> 322.48232 | T27: =N27/P27 -> 1.6378378 | U27: =(I27-L27)/(Q27-L27)*100 -> 90.808824
A28: 2026-10-23 | B28: WR | C28: 2 | D28: 48.5 | E28: 17 | F28: 7.5 | G28: 30 | H28: 1265.74 | I28: 4.63 | J28: 56.17 | K28: =I28+J28 -> 60.8 | L28: 0.248 | M28: 3.48 | N28: =L28+M28 -> 3.728 | O28: 2.7 | P28: =O28-0.22 -> 2.48 | Q28: 4.81 | R28: =E28/F28 -> 2.2666667 | S28: =H28/N28 -> 339.52253 | T28: =N28/P28 -> 1.5032258 | U28: =(I28-L28)/(Q28-L28)*100 -> 96.054362
A29: 2026-10-23 | B29: WR | C29: 3 | D29: 33 | E29: 16 | F29: 8 | G29: 29 | H29: 949.14 | I29: 3.73 | J29: 45.27 | K29: =I29+J29 -> 49 | L29: 0.198 | M29: 2.69 | N29: =L29+M29 -> 2.888 | O29: 2.16 | P29: =O29-0.22 -> 1.94 | Q29: 4.01 | R29: =E29/F29 -> 2 | S29: =H29/N29 -> 328.64958 | T29: =N29/P29 -> 1.4886598 | U29: =(I29-L29)/(Q29-L29)*100 -> 92.654774
A30: 2026-10-23 | B30: WR | C30: 4 | D30: 42.2 | E30: 17 | F30: 9.5 | G30: 34 | H30: 1729.91 | J30: 86.89 | K30: =I30+J30 -> 86.89 | M30: 5.89 | N30: =L30+M30 -> 5.89 | O30: 2.24 | P30: =O30-0.22 -> 2.02 | R30: =E30/F30 -> 1.7894737 | S30: =H30/N30 -> 293.70289 | T30: =N30/P30 -> 2.9158416
A31: 2026-10-23 | B31: WR | C31: 5 | D31: 39.2 | E31: 16 | F31: 7.5 | G31: 31 | H31: 1445.85 | J31: 70.17 | K31: =I31+J31 -> 70.17 | M31: 4.61 | N31: =L31+M31 -> 4.61 | O31: 1.39 | P31: =O31-0.22 -> 1.17 | R31: =E31/F31 -> 2.1333333 | S31: =H31/N31 -> 313.63341 | T31: =N31/P31 -> 3.9401709
A32: 2026-10-23 | B32: WR | C32: 6 | D32: 34.1 | E32: 16 | F32: 9.4 | G32: 33 | H32: 1634.65 | J32: 87.22 | K32: =I32+J32 -> 87.22 | M32: 5.67 | N32: =L32+M32 -> 5.67 | O32: 2.4 | P32: =O32-0.22 -> 2.18 | R32: =E32/F32 -> 1.7021277 | S32: =H32/N32 -> 288.29806 | T32: =N32/P32 -> 2.6009174
A33: 2026-10-23 | B33: WR | C33: 7 | D33: 35.8 | E33: 16.4 | F33: 7.7 | G33: 33 | H33: 1315.15 | J33: 63.22 | K33: =I33+J33 -> 63.22 | M33: 3.89 | N33: =L33+M33 -> 3.89 | O33: 1.01 | P33: =O33-0.22 -> 0.79 | R33: =E33/F33 -> 2.1298701 | S33: =H33/N33 -> 338.08483 | T33: =N33/P33 -> 4.9240506
A34: 2026-10-23 | B34: WR | C34: 8 | D34: 43.6 | E34: 16.5 | F34: 7.9 | G34: 30 | H34: 1075.86 | J34: 49.6 | K34: =I34+J34 -> 49.6 | M34: 3.5 | N34: =L34+M34 -> 3.5 | O34: 3.16 | P34: =O34-0.22 -> 2.94 | R34: =E34/F34 -> 2.0886076 | S34: =H34/N34 -> 307.38857 | T34: =N34/P34 -> 1.1904762
A35: 2026-10-23 | B35: WDR | C35: 1 | D35: 37 | E35: 17 | F35: 8.5 | G35: 35 | H35: 1585.15 | I35: 4.49 | J35: 74.89 | K35: =I35+J35 -> 79.38 | L35: 0.338 | M35: 5.48 | N35: =L35+M35 -> 5.818 | O35: 2.54 | P35: =O35-0.22 -> 2.32 | Q35: 4.67 | R35: =E35/F35 -> 2 | S35: =H35/N35 -> 272.45617 | T35: =N35/P35 -> 2.5077586 | U35: =(I35-L35)/(Q35-L35)*100 -> 95.844875
A36: 2026-10-23 | B36: WDR | C36: 2 | D36: 37.1 | E36: 15.5 | F36: 7 | G36: 33 | H36: 1094.48 | I36: 3.67 | J36: 53.49 | K36: =I36+J36 -> 57.16 | L36: 0.203 | M36: 3.2 | N36: =L36+M36 -> 3.403 | O36: 1.48 | P36: =O36-0.22 -> 1.26 | Q36: 3.9 | R36: =E36/F36 -> 2.2142857 | S36: =H36/N36 -> 321.6221 | T36: =N36/P36 -> 2.7007937 | U36: =(I36-L36)/(Q36-L36)*100 -> 93.77874
A37: 2026-10-23 | B37: WDR | C37: 3 | D37: 30.5 | E37: 15 | F37: 7.5 | G37: 27 | H37: 888.28 | I37: 4.48 | J37: 42.2 | K37: =I37+J37 -> 46.68 | L37: 0.236 | M37: 2.37 | N37: =L37+M37 -> 2.606 | O37: 1.25 | P37: =O37-0.22 -> 1.03 | Q37: 4.81 | R37: =E37/F37 -> 2 | S37: =H37/N37 -> 340.85955 | T37: =N37/P37 -> 2.5300971 | U37: =(I37-L37)/(Q37-L37)*100 -> 92.785308
A38: 2026-10-23 | B38: WDR | C38: 4 | D38: 48.6 | E38: 16 | F38: 8 | G38: 28 | H38: 1145.11 | J38: 55.62 | K38: =I38+J38 -> 55.62 | M38: 3.51 | N38: =L38+M38 -> 3.51 | O38: 1.05 | P38: =O38-0.22 -> 0.83 | R38: =E38/F38 -> 2 | S38: =H38/N38 -> 326.24217 | T38: =N38/P38 -> 4.2289157
A39: 2026-10-23 | B39: WDR | C39: 5 | D39: 37.6 | E39: 14 | F39: 7 | G39: 28 | H39: 934.92 | J39: 43.62 | K39: =I39+J39 -> 43.62 | M39: 3.02 | N39: =L39+M39 -> 3.02 | O39: 1.74 | P39: =O39-0.22 -> 1.52 | R39: =E39/F39 -> 2 | S39: =H39/N39 -> 309.57616 | T39: =N39/P39 -> 1.9868421
A40: 2026-10-23 | B40: WDR | C40: 6 | D40: 36.2 | E40: 16.4 | F40: 8.7 | G40: 31 | H40: 1312.42 | J40: 63.97 | K40: =I40+J40 -> 63.97 | M40: 4.71 | N40: =L40+M40 -> 4.71 | O40: 2.05 | P40: =O40-0.22 -> 1.83 | R40: =E40/F40 -> 1.8850575 | S40: =H40/N40 -> 278.64544 | T40: =N40/P40 -> 2.5737705
...

Sheet 평균값
A1: 날짜 | B1: Treatment | C1: SPAD | D1: 엽장 | E1: 엽폭 | F1: 엽수 | G1: 엽면적 | H1: 지상부 생체중 | K1: 지상부 건조중 | N1: 지하부 건조중 (배지 포함) | O1: 지하부 건조중 | P1: 포화중(TW) | Q1: LSI (cm/cm) | R1: SLA (cm2/g) | S1: S/R ratio (g/g) | T1: RWC(%)
H2: TW측정용 | I2: 나머지 | J2: 전체 | K2: TW측정용 | L2: 나머지 | M2: 전체
A3: 2026-10-07 | B3: CR | C3: =AVERAGE('파괴조사 데이터'!D3:D10) -> 40.175 | D3: =AVERAGE('파괴조사 데이터'!E3:E10) -> 13.125 | E3: =AVERAGE('파괴조사 데이터'!F3:F10) -> 6.95 | F3: =AVERAGE('파괴조사 데이터'!G3:G10) -> 13.375 | G3: =AVERAGE('파괴조사 데이터'!H3:H10) -> 260.65875 | H3: =AVERAGE('파괴조사 데이터'!I3:I10) -> 2.16375 | I3: =AVERAGE('파괴조사 데이터'!J3:J10) -> 7.865 | J3: =AVERAGE('파괴조사 데이터'!K3:K10) -> 10.02875 | ... T3: =AVERAGE('파괴조사 데이터'!U3:U10) -> 88.053135
A4: 2026-10-23 | B4: CR | C4: =AVERAGE('파괴조사 데이터'!D11:D18) -> 43.1875 | D4: =AVERAGE('파괴조사 데이터'!E11:E18) -> 16.25 | E4: =AVERAGE('파괴조사 데이터'!F11:F18) -> 9 | F4: =AVERAGE('파괴조사 데이터'!G11:G18) -> 35.625 | G4: =AVERAGE('파괴조사 데이터'!H11:H18) -> 1599.3338 | H4: =AVERAGE('파괴조사 데이터'!I11:I18) -> 6.61 | I4: =AVERAGE('파괴조사 데이터'!J11:J18) -> 87.40625 | J4: =AVERAGE('파괴조사 데이터'!K11:K18) -> 89.885 | ... P4: =AVERAGE('파괴조사 데이터'!Q11:Q18) -> 7.18 | Q4: =AVERAGE('파괴조사 데이터'!R4:R11) -> 1.8685669 | R4: =AVERAGE('파괴조사 데이터'!S11:S18) -> 252.48465 | S4: =AVERAGE('파괴조사 데이터'!T11:T18) -> 1.6225262 | T4: =AVERAGE('파괴조사 데이터'!U11:U18) -> 92.134795
A5: 2026-10-23 | B5: DR | C5: =AVERAGE('파괴조사 데이터'!D19:D26) -> 44.4875 | D5: =AVERAGE('파괴조사 데이터'!E19:E26) -> 16.275 | E5: =AVERAGE('파괴조사 데이터'!F19:F26) -> 8.975 | F5: =AVERAGE('파괴조사 데이터'!G19:G26) -> 31.125 | G5: =AVERAGE('파괴조사 데이터'!H19:H26) -> 1289.3025 | H5: =AVERAGE('파괴조사 데이터'!I19:I26) -> 4.6666667 | I5: =AVERAGE('파괴조사 데이터'!J19:J26) -> 61.72125 | J5: =AVERAGE('파괴조사 데이터'!K19:K26) -> 63.47125 | ... P5: =AVERAGE('파괴조사 데이터'!Q19:Q26) -> 5.16 | Q5: =AVERAGE('파괴조사 데이터'!R5:R12) -> 1.811659 | R5: =AVERAGE('파괴조사 데이터'!S19:S26) -> 238.73637 | S5: =AVERAGE('파괴조사 데이터'!T19:T26) -> 2.2683141 | T5: =AVERAGE('파괴조사 데이터'!U19:U26) -> 90.028971
A6: 2026-10-23 | B6: WR | C6: =AVERAGE('파괴조사 데이터'!D27:D34) -> 39.3875 | D6: =AVERAGE('파괴조사 데이터'!E27:E34) -> 16.2375 | E6: =AVERAGE('파괴조사 데이터'!F27:F34) -> 8.1875 | F6: =AVERAGE('파괴조사 데이터'!G27:G34) -> 31.375 | G6: =AVERAGE('파괴조사 데이터'!H27:H34) -> 1348.0338 | H6: =AVERAGE('파괴조사 데이터'!I27:I34) -> 4.0233333 | I6: =AVERAGE('파괴조사 데이터'!J27:J34) -> 64.84125 | J6: =AVERAGE('파괴조사 데이터'!K27:K34) -> 66.35 | ... P6: =AVERAGE('파괴조사 데이터'!Q27:Q34) -> 4.2933333 | Q6: =AVERAGE('파괴조사 데이터'!R6:R13) -> 1.7524058 | R6: =AVERAGE('파괴조사 데이터'!S27:S34) -> 316.47027 | S6: =AVERAGE('파괴조사 데이터'!T27:T34) -> 2.5251475 | T6: =AVERAGE('파괴조사 데이터'!U27:U34) -> 93.172653
A7: 2026-10-23 | B7: WDR | C7: =AVERAGE('파괴조사 데이터'!D35:D42) -> 37.675 | D7: =AVERAGE('파괴조사 데이터'!E35:E42) -> 15.2 | E7: =AVERAGE('파괴조사 데이터'!F35:F42) -> 7.6875 | F7: =AVERAGE('파괴조사 데이터'!G35:G42) -> 30.375 | G7: =AVERAGE('파괴조사 데이터'!H35:H42) -> 1138.135 | H7: =AVERAGE('파괴조사 데이터'!I35:I42) -> 4.2133333 | I7: =AVERAGE('파괴조사 데이터'!J35:J42) -> 53.855 | J7: =AVERAGE('파괴조사 데이터'!K35:K42) -> 55.435 | ... P7: =AVERAGE('파괴조사 데이터'!Q35:Q42) -> 4.46 | Q7: =AVERAGE('파괴조사 데이터'!R7:R14) -> 1.7489335 | R7: =AVERAGE('파괴조사 데이터'!S35:S42) -> 314.18858 | S7: =AVERAGE('파괴조사 데이터'!T35:T42) -> 2.7033364 | T7: =AVERAGE('파괴조사 데이터'!U35:U42) -> 94.136308
