Workbook

Sheet 증산량(ETc,침ETc)
A1: 날짜 | B1: Treatment | C1: Repeat | D1: 관수 전(g) | E1: 관수 후(g) | F1: 증산량(g)
A2: 2026-10-11 | B2: ETc | C2: 1 | D2: 749.3 | E2: 889.1
A3: 2026-10-11 | B3: ETc | C3: 2 | D3: 842.3 | E3: 991.5
A4: 2026-10-11 | B4: ETc | C4: 3 | D4: 728.7 | E4: 864.8
A5: 2026-10-11 | B5: 침수 ETc | C5: 1 | D5: 1253.1 | E5: 1251
A6: 2026-10-11 | B6: 침수 ETc | C6: 2 | D6: 1197.5 | E6: 1195.1
A7: 2026-10-11 | B7: 침수 ETc | C7: 3 | D7: 1186.5 | E7: 1185
A8: 2026-10-12 | B8: ETc | C8: 1 | D8: 763.8 | E8: 896.1 | F8: =E2-D8 -> 125.3
A9: 2026-10-12 | B9: ETc | C9: 2 | D9: 865.1 | E9: 1004.3 | F9: =E3-D9 -> 126.4
A10: 2026-10-12 | B10: ETc | C10: 3 | D10: 731.3 | E10: 856.1 | F10: =E4-D10 -> 133.5
A11: 2026-10-12 | B11: 침수 ETc | C11: 1 | D11: 1177.8 | E11: 1221.8 | F11: =E5-D11 -> 73.2
A12: 2026-10-12 | B12: 침수 ETc | C12: 2 | D12: 1118.6 | E12: 1164.5 | F12: =E6-D12 -> 76.5
A13: 2026-10-12 | B13: 침수 ETc | C13: 3 | D13: 1101.6 | E13: 1153.1 | F13: =E7-D13 -> 83.4
A14: 2026-10-13 | B14: ETc | C14: 1 | D14: 811.7 | E14: 904.9 | F14: =E8-D14 -> 84.4
A15: 2026-10-13 | B15: ETc | C15: 2 | D15: 922.4 | E15: 1007.4 | F15: =E9-D15 -> 81.9
A16: 2026-10-13 | B16: ETc | C16: 3 | D16: 764.7 | E16: 853.7 | F16: =E10-D16 -> 91.4
A17: 2026-10-13 | B17: ETc | C17: 4 | D17: 1039.8 | E17: 1115.9
A18: 2026-10-13 | B18: ETc | C18: 5 | D18: 891.2 | E18: 971
A19: 2026-10-13 | B19: ETc | C19: 6 | D19: 1042.9 | E19: 1122.7
A20: 2026-10-13 | B20: 침수 ETc | C20: 1 | D20: 1162.2 | E20: 1216.1 | F20: =E11-D20 -> 59.6
A21: 2026-10-13 | B21: 침수 ETc | C21: 2 | D21: 1106.6 | E21: 1155.7 | F21: =E12-D21 -> 57.9
A22: 2026-10-13 | B22: 침수 ETc | C22: 3 | D22: 1105 | E22: 1151.9 | F22: =E13-D22 -> 48.1
A23: 2026-10-13 | B23: 침수 ETc | C23: 4 | D23: 1131.1 | E23: 1196
A24: 2026-10-13 | B24: 침수 ETc | C24: 5 | D24: 1172.9 | E24: 1212.9
A25: 2026-10-13 | B25: 침수 ETc | C25: 6 | D25: 1185.1 | E25: 1237.7
A26: 2026-10-14 | B26: ETc | C26: 1 | D26: 823.3 | E26: 907.7 | F26: =E14-D26 -> 81.6
A27: 2026-10-14 | B27: ETc | C27: 2 | D27: 917.6 | E27: 990.5 | F27: =E15-D27 -> 89.8
A28: 2026-10-14 | B28: ETc | C28: 3 | D28: 770 | E28: 850.7 | F28: =E16-D28 -> 83.7
A29: 2026-10-14 | B29: ETc | C29: 4 | D29: 1034.1 | E29: 1115.2 | F29: =E17-D29 -> 81.8
A30: 2026-10-14 | B30: ETc | C30: 5 | D30: 900 | E30: 982.1 | F30: =E18-D30 -> 71
A31: 2026-10-14 | B31: ETc | C31: 6 | D31: 1028.3 | E31: 1100 | F31: =E19-D31 -> 94.4
A32: 2026-10-14 | B32: 침수 ETc | C32: 1 | D32: 1153.7 | E32: 1210.9 | F32: =E20-D32 -> 62.4
A33: 2026-10-14 | B33: 침수 ETc | C33: 2 | D33: 1096.4 | E33: 1152 | F33: =E21-D33 -> 59.3
A34: 2026-10-14 | B34: 침수 ETc | C34: 3 | D34: 1087 | E34: 1144.4 | F34: =E22-D34 -> 64.9
A35: 2026-10-14 | B35: 침수 ETc | C35: 4 | D35: 1116.2 | E35: 1191.4 | F35: =E23-D35 -> 79.8
A36: 2026-10-14 | B36: 침수 ETc | C36: 5 | D36: 1145.1 | E36: 1204.8 | F36: =E24-D36 -> 67.8
A37: 2026-10-14 | B37: 침수 ETc | C37: 6 | D37: 1150.8 | E37: 1224.5 | F37: =E25-D37 -> 86.9
... A133: 2026-10-22 | B133: 침수 ETc | C133: 6 | D133: 1084 | E133: 1179.1 | F133: =E121-D133 -> 98.3
A134: 2026-10-23 | B134: ETc | C134: 1 | D134: 868.8 | F134: =E122-D134 -> 92.7
A135: 2026-10-23 | B135: ETc | C135: 2 | D135: 648.1 | F135: =E123-D135 -> 130.7
...

Sheet 관수량(ETc50,침ETc,침50)
A1: 날짜 | B1: Treatment | C1: Repeat | D1: 관수 전(g) | E1: 관수 후(g) | F1: 관수량(g)
A2: 2026-10-12 | B2: ETc 50 | C2: 1 | D2: 644.9 | E2: 707.6 | F2: =E2-D2 -> 62.7
A3: 2026-10-12 | B3: ETc 50 | C3: 2 | D3: 940.5 | E3: 1004.2 | F3: =E3-D3 -> 63.7
A4: 2026-10-12 | B4: ETc 50 | C4: 3 | D4: 616 | E4: 674.6 | F4: =E4-D4 -> 58.6
A5: 2026-10-12 | B5: 침수50 | C5: 1 | D5: 1138.2 | E5: 1189.7 | F5: =E5-D5 -> 51.5
A6: 2026-10-12 | B6: 침수50 | C6: 2 | D6: 1198.8 | E6: 1236.6 | F6: =E6-D6 -> 37.8
A7: 2026-10-12 | B7: 침수50 | C7: 3 | D7: 1145.5 | E7: 1186.4 | F7: =E7-D7 -> 40.9
A8: 2026-10-13 | B8: ETc 50 | C8: 1 | D8: 629.1 | E8: 669.1 | F8: =E8-D8 -> 40
A9: 2026-10-13 | B9: ETc 50 | C9: 2 | D9: 950.8 | E9: 990.8 | F9: =E9-D9 -> 40
A10: 2026-10-13 | B10: ETc 50 | C10: 3 | D10: 613.4 | E10: 655.9 | F10: =E10-D10 -> 42.5
A11: 2026-10-13 | B11: ETc 50 | C11: 4 | D11: 796.4 | E11: 836.6 | F11: =E11-D11 -> 40.2
A12: 2026-10-13 | B12: 침수 ETc | C12: 7 | D12: 1212.8 | E12: 1240.6 | F12: =E12-D12 -> 27.8
A13: 2026-10-13 | B13: 침수 ETc | C13: 8 | D13: 1211.8 | E13: 1231.5 | F13: =E13-D13 -> 19.7
... A127: 2026-10-22 | B127: 침수50 | C127: 4 | D127: 1038.5 | E127: 1088.9 | F127: =E127-D127 -> 50.4
A128: 2026-10-23 | B128: ETc 50 | C128: 1 | D128: 504.6 | E128: =D128 -> 504.6 | F128: =E128-D128 -> 0
A129: 2026-10-23 | B129: ETc 50 | C129: 2 | D129: 538.5 | E129: =D129 -> 538.5 | F129: =E129-D129 -> 0
A130: 2026-10-23 | B130: ETc 50 | C130: 3 | D130: 458.8 | E130: =D130 -> 458.8 | F130: =E130-D130 -> 0
A131: 2026-10-23 | B131: ETc 50 | C131: 4 | D131: 501.4 | E131: =D131 -> 501.4 | F131: =E131-D131 -> 0
A132: 2026-10-23 | B132: 침수 ETc | C132: 7 | D132: 1151.8 | E132: =D132 -> 1151.8 | F132: =E132-D132 -> 0
A133: 2026-10-23 | B133: 침수 ETc | C133: 8 | D133: 1146 | E133: =D133 -> 1146 | F133: =E133-D133 -> 0
A134: 2026-10-23 | B134: 침수 ETc | C134: 9 | D134: 1018.2 | E134: =D134 -> 1018.2 | F134: =E134-D134 -> 0
A135: 2026-10-23 | B135: 침수 ETc | C135: 10 | D135: 1123.3 | E135: =D135 -> 1123.3 | F135: =E135-D135 -> 0
A136: 2026-10-23 | B136: 침수50 | C136: 1 | D136: 618.5 | E136: =D136 -> 618.5 | F136: =E136-D136 -> 0
A137: 2026-10-23 | B137: 침수50 | C137: 2 | D137: 878.2 | E137: =D137 -> 878.2 | F137: =E137-D137 -> 0
A138: 2026-10-23 | B138: 침수50 | C138: 3 | D138: 926.2 | E138: =D138 -> 926.2 | F138: =E138-D138 -> 0
A139: 2026-10-23 | B139: 침수50 | C139: 4 | D139: 1000 | E139: =D139 -> 1000 | F139: =E139-D139 -> 0

Sheet 로드셀관수량(ETc)
A1: 날짜 | B1: Treatment | C1: 관수 전(kg) | D1: 관수 후(kg) | E1: 로드셀관수량(g) | F1: 평균관수량(g)
A2: 2026-10-12 | B2: ETc | C2: 5.246 | D2: 5.791 | E2: =(D2-C2)*1000 -> 545 | F2: =E2/4 -> 136.25
A3: 2026-10-13 | B3: ETc | C3: 5.521 | D3: 5.891 | E3: =(D3-C3)*1000 -> 370 | F3: =E3/4 -> 92.5
A4: 2026-10-14 | B4: ETc | C4: 5.505 | D4: 5.875 | E4: =(D4-C4)*1000 -> 370 | F4: =E4/4 -> 92.5
A5: 2026-10-15 | B5: ETc | C5: 5.301 | D5: 5.903 | E5: =(D5-C5)*1000 -> 602 | F5: =E5/4 -> 150.5
A6: 2026-10-16 | B6: ETc | C6: 5.346 | D6: 5.839 | E6: =(D6-C6)*1000 -> 493 | F6: =E6/4 -> 123.25
A7: 2026-10-17 | B7: ETc | C7: 5.345 | D7: 5.832 | E7: =(D7-C7)*1000 -> 487 | F7: =E7/4 -> 121.75
A8: 2026-10-18 | B8: ETc | C8: 5.363 | D8: 5.822 | E8: =(D8-C8)*1000 -> 459 | F8: =E8/4 -> 114.75
A9: 2026-10-19 | B9: ETc | C9: 6.006 | D9: 6.123 | E9: =(D9-C9)*1000 -> 117 | F9: =E9/4 -> 29.25
A10: 2026-10-20 | B10: ETc | C10: 5.857 | D10: 6.106 | E10: =(D10-C10)*1000 -> 249 | F10: =E10/4 -> 62.25
A11: 2026-10-21 | B11: ETc | C11: 6.04 | D11: 6.132 | E11: =(D11-C11)*1000 -> 92 | F11: =E11/4 -> 23
A12: 2026-10-22 | B12: ETc | C12: 5.715 | D12: 6.117 | E12: =(D12-C12)*1000 -> 402 | F12: =E12/4 -> 100.5
A13: 2026-10-23 | B13: ETc | C13: 0 | D13: 0 | E13: =(D13-C13)*1000 -> 0 | F13: =E13/4 -> 0

Sheet 관수량 비교
A1: 날짜 | B1: Treatment | C1: 목표관수량(g) | D1: 관수 시간(s) | E1: 평균관수량(g) | F1: 관수량 차이 | G1: 비고
A2: 2026-10-12 | B2: ETc | C2: =AVERAGE('증산량(ETc,침ETc)'!F8:F10) -> 128.4 | D2: =C2/0.56 -> 229.28571 | E2: ='로드셀관수량(ETc)'!F2 -> 136.25 | F2: =E2-C2 -> 7.85
A3: 2026-10-12 | B3: ETc 50 | C3: =C2/2 -> 64.2 | D3: =C3/0.56 -> 114.64286 | E3: =AVERAGE('관수량(ETc50,침ETc,침50)'!F2:F4) -> 61.666667 | F3: =E3-C3 -> -2.5333333
A4: 2026-10-12 | B4: 침수 ETc | C4: =AVERAGE('증산량(ETc,침ETc)'!F11:F13) -> 77.7 | D4: =C4/0.56 -> 138.75 | F4: =E4-C4 -> -77.7
A5: 2026-10-12 | B5: 침수 50 | C5: =C4/2 -> 38.85 | D5: =C5/0.56 -> 69.375 | E5: =AVERAGE('관수량(ETc50,침ETc,침50)'!F5:F7) -> 43.4 | F5: =E5-C5 -> 4.55
A6: 2026-10-13 | B6: ETc | C6: =AVERAGE('증산량(ETc,침ETc)'!F14:F16) -> 85.9 | D6: =C6/0.56 -> 153.39286 | E6: ='로드셀관수량(ETc)'!F3 -> 92.5 | F6: =E6-C6 -> 6.6
A7: 2026-10-13 | B7: ETc 50 | C7: =C6/2 -> 42.95 | D7: =C7/0.56 -> 76.696429 | E7: =AVERAGE('관수량(ETc50,침ETc,침50)'!F8:F11) -> 40.675 | F7: =E7-C7 -> -2.275
A8: 2026-10-13 | B8: 침수 ETc | C8: =AVERAGE('증산량(ETc,침ETc)'!F20:F22) -> 55.2 | D8: =C8/0.56 -> 98.571429 | E8: =AVERAGE('관수량(ETc50,침ETc,침50)'!F12:F15) -> 27.4 | F8: =E8-C8 -> -27.8
A9: 2026-10-13 | B9: 침수 50 | C9: =C8/2 -> 27.6 | D9: =C9/0.56 -> 49.285714 | E9: =AVERAGE('관수량(ETc50,침ETc,침50)'!F16:F19) -> 24.675 | F9: =E9-C9 -> -2.925
A10: 2026-10-14 | B10: ETc | C10: =AVERAGE('증산량(ETc,침ETc)'!F26:F31) -> 83.716667 | D10: =C10/0.56 -> 149.49405 | E10: ='로드셀관수량(ETc)'!F4 -> 92.5 | F10: =E10-C10 -> 8.7833333
A11: 2026-10-14 | B11: ETc 50 | C11: =C10/2 -> 41.858333 | D11: =C11/0.56 -> 74.747024 | E11: =AVERAGE('관수량(ETc50,침ETc,침50)'!F20:F23) -> 37.2 | F11: =E11-C11 -> -4.6583333
A12: 2026-10-14 | B12: 침수 ETc | C12: =AVERAGE('증산량(ETc,침ETc)'!F32:F37) -> 70.183333 | D12: =C12/0.56 -> 125.32738 | E12: =AVERAGE('관수량(ETc50,침ETc,침50)'!F24:F27) -> 50.9 | F12: =E12-C12 -> -19.283333
A13: 2026-10-14 | B13: 침수 50 | C13: =C12/2 -> 35.091667 | D13: =C13/0.56 -> 62.66369 | E13: =AVERAGE('관수량(ETc50,침ETc,침50)'!F28:F31) -> 35.975 | F13: =E13-C13 -> 0.88333333
A14: 2026-10-15 | B14: ETc | C14: =AVERAGE('증산량(ETc,침ETc)'!F38:F43) -> 143.8 | D14: =C14/0.56 -> 256.78571 | E14: ='로드셀관수량(ETc)'!F5 -> 150.5 | F14: =E14-C14 -> 6.7
A15: 2026-10-15 | B15: ETc 50 | C15: =C14/2 -> 71.9 | D15: =C15/0.56 -> 128.39286 | E15: =AVERAGE('관수량(ETc50,침ETc,침50)'!F32:F35) -> 65.525 | F15: =E15-C15 -> -6.375
A16: 2026-10-15 | B16: 침수 ETc | C16: =AVERAGE('증산량(ETc,침ETc)'!F44:F49) -> 118.21667 | D16: =C16/0.56 -> 211.10119 | E16: =AVERAGE('관수량(ETc50,침ETc,침50)'!F36:F39) -> 81.95 | F16: =E16-C16 -> -36.266667
A17: 2026-10-15 | B17: 침수 50 | C17: =C16/2 -> 59.108333 | D17: =C17/0.56 -> 105.5506 | E17: =AVERAGE('관수량(ETc50,침ETc,침50)'!F40:F43) -> 54.575 | F17: =E17-C17 -> -4.5333333
A18: 2026-10-16 | B18: ETc | C18: =AVERAGE('증산량(ETc,침ETc)'!F50:F55) -> 117.91667 | D18: =C18/0.56 -> 210.56548 | E18: ='로드셀관수량(ETc)'!F6 -> 123.25 | F18: =E18-C18 -> 5.3333333
A19: 2026-10-16 | B19: ETc 50 | C19: =C18/2 -> 58.958333 | D19: =C19/0.56 -> 105.28274 | E19: =AVERAGE('관수량(ETc50,침ETc,침50)'!F44:F47) -> 50.025 | F19: =E19-C19 -> -8.9333333
A20: 2026-10-16 | B20: 침수 ETc | C20: =AVERAGE('증산량(ETc,침ETc)'!F56:F61) -> 109.55 | D20: =C20/0.56 -> 195.625 | E20: =AVERAGE('관수량(ETc50,침ETc,침50)'!F48:F51) -> 84.6 | F20: =E20-C20 -> -24.95
A21: 2026-10-16 | B21: 침수 50 | C21: =C20/2 -> 54.775 | D21: =C21/0.56 -> 97.8125 | E21: =AVERAGE('관수량(ETc50,침ETc,침50)'!F52:F55) -> 46.85 | F21: =E21-C21 -> -7.925
A22: 2026-10-17 | B22: ETc | C22: =AVERAGE('증산량(ETc,침ETc)'!F62:F67) -> 107.71667 | D22: =C22/0.56 -> 192.35119 | E22: ='로드셀관수량(ETc)'!F7 -> 121.75 | F22: =E22-C22 -> 14.033333
A23: 2026-10-17 | B23: ETc 50 | C23: =C22/2 -> 53.858333 | D23: =C23/0.56 -> 96.175595 | E23: =AVERAGE('관수량(ETc50,침ETc,침50)'!F56:F59) -> 43.125 | F23: =E23-C23 -> -10.733333
A24: 2026-10-17 | B24: 침수 ETc | C24: =AVERAGE('증산량(ETc,침ETc)'!F68:F73) -> 93.15 | D24: =C24/0.56 -> 166.33929 | E24: =AVERAGE('관수량(ETc50,침ETc,침50)'!F60:F63) -> 88.025 | F24: =E24-C24 -> -5.125
A25: 2026-10-17 | B25: 침수 50 | C25: =C24/2 -> 46.575 | D25: =C25/0.56 -> 83.169643 | E25: =AVERAGE('관수량(ETc50,침ETc,침50)'!F64:F67) -> 44.975 | F25: =E25-C25 -> -1.6
A26: 2026-10-18 | B26: ETc | C26: =AVERAGE('증산량(ETc,침ETc)'!F74:F79) -> 122.5 | D26: =C26/0.56 -> 218.75 | E26: ='로드셀관수량(ETc)'!F8 -> 114.75 | F26: =E26-C26 -> -7.75 | G26: 107g으로 잘못 계산
A27: 2026-10-18 | B27: ETc 50 | C27: =C26/2 -> 61.25 | D27: =C27/0.56 -> 109.375 | E27: =AVERAGE('관수량(ETc50,침ETc,침50)'!F68:F71) -> 52.925 | F27: =E27-C27 -> -8.325
A28: 2026-10-18 | B28: 침수 ETc | C28: =AVERAGE('증산량(ETc,침ETc)'!F80:F85) -> 89.333333 | D28: =C28/0.56 -> 159.52381 | E28: =AVERAGE('관수량(ETc50,침ETc,침50)'!F72:F75) -> 71.85 | F28: =E28-C28 -> -17.483333
A29: 2026-10-18 | B29: 침수 50 | C29: =C28/2 -> 44.666667 | D29: =C29/0.56 -> 79.761905 | E29: =AVERAGE('관수량(ETc50,침ETc,침50)'!F76:F79) -> 45.125 | F29: =E29-C29 -> 0.45833333
A30: 2026-10-19 | B30: ETc | C30: =AVERAGE('증산량(ETc,침ETc)'!F86:F91) -> 24.85 | D30: =C30/0.56 -> 44.375 | E30: ='로드셀관수량(ETc)'!F9 -> 29.25 | F30: =E30-C30 -> 4.4
A31: 2026-10-19 | B31: ETc 50 | C31: =C30/2 -> 12.425 | D31: =C31/0.56 -> 22.1875 | E31: =AVERAGE('관수량(ETc50,침ETc,침50)'!F80:F83) -> 12.475 | F31: =E31-C31 -> 0.05
A32: 2026-10-19 | B32: 침수 ETc | C32: =AVERAGE('증산량(ETc,침ETc)'!F92:F97) -> 22.45 | D32: =C32/0.56 -> 40.089286 | E32: =AVERAGE('관수량(ETc50,침ETc,침50)'!F84:F87) -> 26.825 | F32: =E32-C32 -> 4.375
A33: 2026-10-19 | B33: 침수 50 | C33: =C32/2 -> 11.225 | D33: =C33/0.56 -> 20.044643 | E33: =AVERAGE('관수량(ETc50,침ETc,침50)'!F88:F91) -> 12.275 | F33: =E33-C33 -> 1.05
A34: 2026-10-20 | B34: ETc | C34: =AVERAGE('증산량(ETc,침ETc)'!F98:F103) -> 53.3 | D34: =C34/0.56 -> 95.178571 | E34: ='로드셀관수량(ETc)'!F10 -> 62.25 | F34: =E34-C34 -> 8.95
A35: 2026-10-20 | B35: ETc 50 | C35: =C34/2 -> 26.65 | D35: =C35/0.56 -> 47.589286 | E35: =AVERAGE('관수량(ETc50,침ETc,침50)'!F92:F95) -> 25.65 | F35: =E35-C35 -> -1
A36: 2026-10-20 | B36: 침수 ETc | C36: =AVERAGE('증산량(ETc,침ETc)'!F104:F109) -> 46.85 | D36: =C36/0.56 -> 83.660714 | E36: =AVERAGE('관수량(ETc50,침ETc,침50)'!F96:F99) -> 53.6 | F36: =E36-C36 -> 6.75
A37: 2026-10-20 | B37: 침수 50 | C37: =C36/2 -> 23.425 | D37: =C37/0.56 -> 41.830357 | E37: =AVERAGE('관수량(ETc50,침ETc,침50)'!F100:F103) -> 24.3 | F37: =E37-C37 -> 0.875
A38: 2026-10-21 | B38: ETc | C38: =AVERAGE('증산량(ETc,침ETc)'!F110:F115) -> 18.25 | D38: =C38/0.56 -> 32.589286 | E38: ='로드셀관수량(ETc)'!F11 -> 23 | F38: =E38-C38 -> 4.75
A39: 2026-10-21 | B39: ETc 50 | C39: =C38/2 -> 9.125 | D39: =C39/0.56 -> 16.294643 | E39: =AVERAGE('관수량(ETc50,침ETc,침50)'!F104:F107) -> 11.2 | F39: =E39-C39 -> 2.075
A40: 2026-10-21 | B40: 침수 ETc | C40: =AVERAGE('증산량(ETc,침ETc)'!F116:F121) -> 16.733333 | D40: =C40/0.56 -> 29.880952 | E40: =AVERAGE('관수량(ETc50,침ETc,침50)'!F108:F111) -> 21.15 | F40: =E40-C40 -> 4.4166667
...
